Workbook
Name _fin1: #REF!
Name _fin1: #REF!
Name _fin1: #REF!
Name _fin2: #REF!
Name _fin2: #REF!
Name _fin2: #REF!
Name _fin3: #REF!
Name _fin3: #REF!
Name _fin3: #REF!
Name _fin4: #REF!
Name _fin4: #REF!
Name _fin5: #REF!
Name _fin5: #REF!
Name _fin6: #REF!
Name _fin6: #REF!
Name _fin7: #REF!
Name _fin7: #REF!
Name _fin8: #REF!
Name _fin8: #REF!
Name _sc5: #REF!
Name _sc5: #REF!
Name _SCH12: #REF!
Name _SCH12: #REF!
Name _SCH1213: #REF!
Name _SCH1213: #REF!
Name _SCH123: #REF!
Name _SCH123: #REF!
Name _SCH13: #REF!
Name _SCH13: #REF!
Name _sch14: #REF!
Name _sch14: #REF!
Name _SCH15: #REF!
Name _SCH15: #REF!
Name _sch1516: #REF!
Name _sch1516: #REF!
Name _SCH5: #REF!
Name _SCH5: #REF!
Name _SCH67: #REF!
Name _SCH67: #REF!
Name _sch6789: #REF!
Name _sch6789: #REF!
Name accts: #REF!
Name accts: #REF!
Name ARCH: #REF!
Name ARCH: #REF!
Name AS2HasNoAutoHeaderFooter: "OFF"
Name Balancesheet: #REF!
Name bkccflow: #REF!
Name bkccflow: #REF!
Name bkcrep: #REF!
Name bkcrep: #REF!
Name bs: #REF!
Name bs: #REF!
Name BSV: #REF!
Name BSV: #REF!
Name CEO: #REF!
Name CEO: #REF!
Name Certificates: #REF!
Name CF_NetIncome: #REF!
Name CF_NetIncome: #REF!

Sheet My Contect
A1: 1
C2: Client Detail | E2: 1 | F2: rounding off
C4: Firm Name | D4: SINGLA STEEL CORPORATION
C5: Partner /Auth.Sign. Name | D5: ASHWANI KUMAR SINGLA
C6: Status | D6: PROPRIETOR
C7: Address | D7: #16/26 17/27, Industrial Area, Dehlon-Sahnewal Road, Paddi | E7: =PROPER(D7) -> #16/26 17/27, Industrial Area, Dehlon-Sahnewal Road, Paddi
C8: City | D8: Ludhiana
C9: State | D9: Punjab
C10: PIN Code | D10: 141206
C11: PAN | D11: ASRPS7924E
C12: Firm Status | D12: Proprietorship Firm | E12: Have to Change Manually
C13: Financial Year Starting from | D13: 45017 | E13: 1st April, 2024
C14: Financial Year Ended | D14: 45382 | E14: 31st March, 2025
C15: Financial Year | D15: 2023-24 | E15: 31.03.2025 | F15: Current Year ending
C16: Assessment Year | D16: 2024-25 | E16: 31.03.2024 | F16: Previous Year ending
C17: Head Office | D17: Ludhiana
C18: Branch | D18: Nil
C19: Nature of Business | D19: Trading
C20: GSTIN | D20: 03ASRPS7924E1ZE
C21: Excise Registration No. | D21: Not Registered
C22: Service Tax Registration No. | D22: Not Registered
C23: Import Export Code | D23: Not Registered
C24: GSTIN
B28: Main Work Sheets | C28: Stock Information | D28: Audit Report Information | E28: Certificate
B30: Trading '!A1 | C30: Stock tallies'!A1 | D30: Frunt!A1 | E30: cerificare 40A(3)'!A1
B32: Profit & Loss'!A1 | C32: Stock Valuation'!A1 | D32: 3CB'!A1 | E32: Certificare Relatives'!A1
B35: Balancesheet!A1 | C35: Excise Duty Details'!A1 | D35: 3CD'!A1 | E35: certificate_269SS & T'!A1
B37: Schedule!A1 | D37: PF & ESI'!A1 | E37: SIGNIFICANT!A1
B39: Depreciation!A1 | D39: 269SS & T'!A1
D41: Annexure-I'!A1
D43: Annexure-II'!A1
D45: Depreciation!A1
C48: Chartered Accountants Detail
C51: Firm Name | D51: KUMAR GUPTA & ASSOCIATES
D52: Chartered Accountants
C53: Address | D53: 193-FF, Nitesh Vihar, Dhandra Road, Dugri
C54: City | D54: Ludhiana
C55: State | D55: Punjab
C56: PIN Code | D56: 141013
C57: Firm PAN | D57: ADAFS7726G
...

Sheet Frunt
A2: HARMAN & COMPANY | H2: LUDHIANA
A3: CHARTERED ACCOUNTANTS | H3: MOBILE:- 8699952068
A7: ='My Contect'!D4 -> SINGLA STEEL CORPORATION
A14: ='My Contect'!D8 -> Ludhiana
A24: Ø | B24: Audit Report for the year ended on 31st March, 2025
A25: Ø | B25: Balance Sheet for the year ended on 31st March, 2025
A34: HARMAN & COMPANY
A35: Chartered Accountants
A36: # 6, 2nd Floor, Nego Complex
A37: Pakhowal Road, Gurdev Nagar
A38: Ludhiana Punjab - 141001
A39: Mobile:- 8699952068

Sheet BS
B1: ='My Contect'!D4 -> SINGLA STEEL CORPORATION
B2: CIN - U17309PB2020PTC052239
B4: =CONCATENATE("Balance Sheet as at ",'My Contect'!E15,"") -> Balance Sheet as at 31.03.2025
E5: (Amount in INR)
B6: PARTICULARS | C6: NOTE NO. | D6: =CONCATENATE("As at ",'My Contect'!E15,"") -> As at 31.03.2025 | E6: =CONCATENATE("As at ",'My Contect'!E16,"") -> As at 31.03.2024 | F6: As at 31.03.2022 | G6: =CONCATENATE("As at ",'My Contect'!E15," Amount (Rs.)") -> As at 31.03.2025 Amount (Rs.) | H6: =CONCATENATE("As at ",'My Contect'!E16," Amount (Rs.)") -> As at 31.03.2024 Amount (Rs.) | I6: As at 31.03.2022 | J6: Trial Total | K6: Check
B8: I. OWNERS’ FUNDS AND LIABILITIES
B9: (1) Proprietors’ Fund
B10: (a) Capital Account | C10: =1 -> 1 | D10: ='BS Lia'!H13 -> 15012174 | E10: ='BS Lia'!I13 -> 12874544 | F10: =I10/'My Contect'!$E$2 -> 0 | G10: ='BS Lia'!H13 -> 15012174 | H10: ='BS Lia'!I13 -> 12874544 | J10: =SUM('Trial 2025'!H11:H11) -> 14177491 | K10: =G10-J10-PL!G30 -> 0
B11: (b) Reserves and Surplus | C11: =C10 -> 1 | D11: ='BS Lia'!E22 -> 0 | E11: ='BS Lia'!F22 -> 0 | F11: =I11/'My Contect'!$E$2 -> 0 | G11: ='BS Lia'!H22 -> 0 | H11: ='BS Lia'!I22 -> 0
D13: =SUM(D10:D12) -> 15012174 | E13: =SUM(E10:E12) -> 12874544 | F13: =SUM(F10:F12) -> 0 | G13: =SUM(G10:G12) -> 15012174 | H13: =SUM(H10:H12) -> 12874544
B15: (2) Non-Current Liabilities
B16: (a) Long-term borrowings | C16: =C11+1 -> 2 | D16: ='BS Lia'!E37 -> 19187969 | E16: ='BS Lia'!F37 -> 38624774 | F16: =I16/'My Contect'!$E$2 -> 0 | G16: ='BS Lia'!H37 -> 19187969 | H16: ='BS Lia'!I37 -> 38624774
B17: (b) Deferred tax liabilities (Net)
B18: (c) Other Long term liabilities
B19: (d) Long-term provisions
B21: (3) Current Liabilities | J21: =SUM('Trial 2025'!H14:H169) -> 44720611 | K21: =G16+G22+G23+G24 -> 44720611 | L21: =J21-K21 -> 0
B22: (a) Short-term borrowings | C22: =C16+1 -> 3 | D22: ='BS Lia'!E61 -> 9407706 | E22: ='BS Lia'!F61 -> 7180440.6 | G22: ='BS Lia'!H61 -> 9407706 | H22: ='BS Lia'!I61 -> 7180440.6
B23: (b) Trade payables | C23: =C22+1 -> 4 | D23: =+'BS Lia'!E85 -> 15846216 | E23: =+'BS Lia'!F85 -> 18488570 | G23: =+'BS Lia'!H85 -> 15846216 | H23: =+'BS Lia'!I85 -> 18488570
B24: (c) Other current liabilities | C24: =C23+1 -> 5 | D24: ='BS Lia'!E106 -> 278720.84 | E24: ='BS Lia'!F106 -> 378414 | F24: =I24/'My Contect'!$E$2 -> 0 | G24: ='BS Lia'!H106 -> 278720.84 | H24: ='BS Lia'!I106 -> 378414
B25: (d) Short-term provisions | C25: =C24+1 -> 6 | D25: ='BS Lia'!E116 -> 38850 | E25: ='BS Lia'!F116 -> 0 | F25: =I25/'My Contect'!$E$2 -> 0 | G25: ='BS Lia'!H116 -> 38850 | H25: ='BS Lia'!I116 -> 0 | L25: ='My Contect'!E15 -> 31.03.2025 | M25: ='My Contect'!E16 -> 31.03.2024
L26: =(G39-G23)*0.75 -> -11168749 | M26: =(H39-H23)*0.75 -> -11181427 | N26: DP on Stock
B27: TOTAL | D27: =SUM(D13:D25) -> 59771636 | E27: =SUM(E13:E25) -> 77546742 | F27: =SUM(F13:F25) -> 0 | G27: =SUM(G13:G25) -> 59771636 | H27: =SUM(H13:H25) -> 77546742 | I27: =SUM(I13:I25) -> 0 | L27: =G40*0.5 -> 27262120 | M27: =H40*0.5 -> 35381031 | N27: DP on Debtors
B28: II. ASSETS | L28: =SUM(L26:L27) -> 16093371 | M28: =SUM(M26:M27) -> 24199604 | N28: Total DP
B29: (1) Non-Current Assets
B30: (a) Property, Plant & Equipment and Intangible assets
B31: (i) Property, Plant & Equipment | C31: =+C25+1 -> 7 | D31: ='FA NEW'!K22 -> 996027 | E31: ='FA NEW'!K59 -> 1168057 | F31: =I31/'My Contect'!$E$2 -> 0 | G31: ='FA NEW'!K22 -> 996027 | H31: ='FA NEW'!K59 -> 1168057 | I31: =H31-1168057 -> 0 | J31: =SUM('Trial 2025'!G66:G71)+'Trial 2025'!G216 -> 1170724.2 | K31: =J31-G31-PL!G17 -> 0 | L31: =K31-G63 -> 8.1956387e-08
B32: (ii) Capital Work-in-Progress | E32: 0
B33: (b) Non-current investment | C33: =C31 -> 7 | D33: ='BS Assets'!E9 -> 0 | E33: ='BS Assets'!F9 -> 0 | G33: ='BS Assets'!H9 -> 0 | H33: ='BS Assets'!I9 -> 0
B34: (c) Deferred tax assets (net) | C34: =C33 -> 7 | D34: ='BS Assets'!E18 -> 0 | E34: ='BS Assets'!F18 -> 0 | F34: =I34/'My Contect'!$E$2 -> 0 | G34: ='BS Assets'!H18 -> 0 | H34: ='BS Assets'!I18 -> 0 | J34: =H34-G34 -> 0
B35: (d) Long-term loans and advances
B36: (e) Other non-current assets | C36: =C34 -> 7 | D36: ='BS Assets'!E26 -> 0 | E36: ='BS Assets'!F26 -> 0 | G36: ='BS Assets'!H26 -> 0 | H36: ='BS Assets'!I26 -> 0
B38: (2) Current Assets | J38: =SUM('Trial 2025'!G11:G171)-J31-'Trial 2025'!G78 -> 57647624 | K38: =G33+G36+G40+G41+G42+G43 -> 57821059 | L38: =J38-K38 -> -173435.16
B39: (a) Inventories | C39: =C36+1 -> 8 | D39: ='BS Assets'!E37 -> 954550 | E39: ='BS Assets'!F37 -> 3580000 | F39: =I39/'My Contect'!$E$2 -> 0 | G39: ='BS Assets'!H37 -> 954550 | H39: ='BS Assets'!I37 -> 3580000
B40: (b) Trade receivables | C40: =C39+1 -> 9 | D40: ='BS Assets'!E46 -> 54524240 | E40: ='BS Assets'!F46 -> 70762062 | F40: =I40/'My Contect'!$E$2 -> 0 | G40: ='BS Assets'!H46 -> 54524240 | H40: ='BS Assets'!I46 -> 70762062
B41: (c) Cash and bank balances | C41: =C40+1 -> 10 | D41: ='BS Assets'!E72 -> 658876 | E41: ='BS Assets'!F72 -> 452524 | F41: =I41/'My Contect'!$E$2 -> 0 | G41: ='BS Assets'!H72 -> 658876 | H41: ='BS Assets'!I72 -> 452524
B42: (d) Short-term loans and advances | C42: =C41+1 -> 11 | D42: ='BS Assets'!E84 -> 2637943.5 | E42: ='BS Assets'!F84 -> 1584099.3 | F42: =I42/'My Contect'!$E$2 -> 0 | G42: ='BS Assets'!H84 -> 2637943.5 | H42: ='BS Assets'!I84 -> 1584099.3
B43: (e) Other current assets | C43: =C42 -> 11 | D43: ='BS Assets'!E94 -> 0 | E43: ='BS Assets'!F94 -> 0 | F43: =I43/'My Contect'!$E$2 -> 0 | G43: ='BS Assets'!H94 -> 0 | H43: ='BS Assets'!I94 -> 0
B45: TOTAL | D45: =SUM(D31:D43) -> 59771636 | E45: =SUM(E31:E43) -> 77546742 | F45: =SUM(F31:F43) -> 0 | G45: =SUM(G31:G43) -> 59771636 | H45: =SUM(H31:H43) -> 77546742 | I45: =SUM(I31:I43) -> 0
B46: Summary of Significant Accounting Policies | C46: 1.1
B47: The accompanying Notes are an integral part of the financial statements .
...

Sheet PL
B1: =BS!B1 -> SINGLA STEEL CORPORATION
B2: =BS!B2 -> CIN - U17309PB2020PTC052239
B4: =CONCATENATE("Profit and Loss Statement for the year ended ",'My Contect'!E15,"") -> Profit and Loss Statement for the year ended 31.03.2025
E5: =BS!E5 -> (Amount in INR)
B6: PARTICULARS | C6: NOTE NO. | D6: =CONCATENATE("For the year ended ",'My Contect'!E15,"") -> For the year ended 31.03.2025 | E6: =CONCATENATE("For the year ended ",'My Contect'!E16,"") -> For the year ended 31.03.2024 | G6: =CONCATENATE("For the year ended ",'My Contect'!E15," Amount (Rs.)") -> For the year ended 31.03.2025 Amount (Rs.) | H6: =CONCATENATE("For the year ended ",'My Contect'!E16," Amount (Rs.)") -> For the year ended 31.03.2024 Amount (Rs.)
B8: I. Revenue from operations | C8: =+BS!C43+1 -> 12 | D8: ='PL Det'!D9 -> 3.4871796e+08 | E8: ='PL Det'!E9 -> 520171626 | G8: ='PL Det'!G9 -> 3.4871796e+08 | H8: ='PL Det'!H9 -> 520171626
B9: II. Other Income | C9: =+C8+1 -> 13 | D9: ='PL Det'!D18 -> 5483 | E9: ='PL Det'!E18 -> 70853 | G9: ='PL Det'!G18 -> 5483 | H9: ='PL Det'!H18 -> 70853
B11: III. Total Income (I +II) | D11: =D8+D9 -> 3.4872344e+08 | E11: =E8+E9 -> 520242479 | G11: =G8+G9 -> 3.4872344e+08 | H11: =H8+H9 -> 520242479 | J11: =SUM('Trial 2025'!H173:H229) -> 3.4872344e+08 | K11: =G11-J11 -> 0
B12: IV. Expenses:
B13: Cost of Material consumed | C13: =C9 -> 13 | D13: ='PL Det'!D26 -> 0 | E13: ='PL Det'!E26 -> 0 | G13: ='PL Det'!G26 -> 0 | H13: ='PL Det'!H26 -> 0
B14: Purchase of Stock-in-Trade | C14: =C13+1 -> 14 | D14: ='PL Det'!D34 -> 3.4133399e+08 | E14: ='PL Det'!E34 -> 5.1174936e+08 | G14: ='PL Det'!G34 -> 3.4133399e+08 | H14: ='PL Det'!H34 -> 5.1174936e+08 | J14: =H8-H14-H15-5861691.88 -> 0
B15: Changes in Inventories of Finished Goods, Work-in-Progress and Stock-in-Trade | C15: =C14+1 -> 15 | D15: ='PL Det'!D50 -> 2625450 | E15: ='PL Det'!E50 -> 2560576 | G15: ='PL Det'!G50 -> 2625450 | H15: ='PL Det'!H50 -> 2560576
B16: Employee Benefit Expense | C16: =C15+1 -> 16 | D16: ='PL Det'!D84 -> 566883 | E16: ='PL Det'!E84 -> 198358 | G16: ='PL Det'!G84 -> 566883 | H16: ='PL Det'!H84 -> 198358
B17: Depreciation and amortisation expense | C17: =C16+1 -> 17 | D17: ='PL Det'!D99 -> 174697.16 | E17: ='PL Det'!E101 -> 196090.53 | G17: ='PL Det'!G99 -> 174697.16 | H17: ='PL Det'!H101 -> 196090.53 | I17: =G17-173435.16 -> 1262 | K17: =G17-'Trial 2025'!G216 -> 1262
B18: Finance costs | C18: =C17+1 -> 18 | D18: ='PL Det'!D113 -> 607712 | E18: ='PL Det'!E113 -> 375573.8 | G18: ='PL Det'!G113 -> 607712 | H18: ='PL Det'!H113 -> 375573.8
B19: Other expenses | C19: =C18+1 -> 19 | D19: ='PL Det'!D134 -> 2541169 | E19: ='PL Det'!E134 -> 3692569.3 | G19: ='PL Det'!G134 -> 2541169 | H19: ='PL Det'!H134 -> 3692569.3
B21: Total Expenses | D21: =SUM(D13:D19) -> 3.4784991e+08 | E21: =SUM(E13:E19) -> 5.1877253e+08 | G21: =SUM(G13:G19) -> 3.4784991e+08 | H21: =SUM(H13:H19) -> 5.1877253e+08 | J21: =SUM('Trial 2025'!G172:G229) -> 3.4522319e+08 | K21: =J21-G14-G16-G17-G18-G19 -> -1262
B23: V. Profit before tax (III -IV) | D23: =D11-D21 -> 873533.16 | E23: =E11-E21 -> 1469953.2 | G23: =G11-G21 -> 873533.16 | H23: =H11-H21 -> 1469953.2 | I23: =889745.16-15000 -> 874745.16 | J23: 1469953.2
I24: =G23-I23 -> -1212 | J24: =H23-J23 -> 9.5460564e-09 | K24: =I24-K21 -> 50
B25: VI. Tax expense:
B26: (1) Current tax | D26: =G26/'My Contect'!$E$2 -> 38850 | E26: =H26/'My Contect'!$E$2 -> 0 | G26: ='[1]COI_AY2020-21'!G31 -> 38850 | H26: 0
B27: (2) Deferred tax | D27: =G27/'My Contect'!$E$2 -> 0 | E27: =H27/'My Contect'!$E$2 -> 0 | G27: =+'BS Assets'!I18-'BS Assets'!H18 -> 0 | H27: 0
B28: (3) Taxes relating to earlier years | D28: =G28/'My Contect'!$E$2 -> 0 | E28: =H28/'My Contect'!$E$2 -> 0 | G28: ='Trial 2025'!G213 -> 0 | H28: 0
B30: VII. Profit/(Loss) for the period (VII-VIII) | D30: =D23-SUM(D26:D28) -> 834683.16 | E30: =E23-SUM(E26:E28) -> 1469953.2 | G30: =G23-SUM(G26:G28) -> 834683.16 | H30: =H23-SUM(H26:H28) -> 1469953.2 | L30: 556292.47 | M30: =H30-L30 -> 913660.77
B32: Summary of Significant Accounting Policies | C32: =BS!C46 -> 1.1
B33: The accompanying Notes are integral part of the financial statements.
B34: This is the Statement of Profit and Loss referred to in our report of even date
B36: =BS!B50 -> FOR KUMAR GUPTA & ASSOCIATES
B37: =BS!B51 -> CHARTERED ACCOUNTANTS | C37: =BS!C51 -> FOR SINGLA STEEL CORPORATION
B38: =BS!B52 -> Firm Registration No. 035355N
B43: =BS!B57 -> (CA. KESHAV GUPTA) | C43: =BS!C57 -> ASHWANI KUMAR SINGLA | G43: =BS!C57 -> ASHWANI KUMAR SINGLA
B44: =BS!B58 -> PROPRIETOR | C44: =BS!C58 -> PROPRIETOR | G44: =BS!C58 -> PROPRIETOR
B45: =BS!B59 -> (M.NO. 553123)
B46: =BS!B60 -> UDIN : 25553123BMLDXE6873
B47: =BS!B61 -> Place : Ludhiana
B48: =BS!B62 -> Dated : 04-Oct-2025
B50: Gross Profit | D50: =D8-D13-D14-D15 -> 4758511.3 | E50: =E8-E13-E14-E15 -> 5861691.9 | F50: =F8-F13-F14-F15 -> 0 | G50: =G8-G13-G14-G15 -> 4758511.3 | H50: =H8-H13-H14-H15 -> 5861691.9 | J50: 4684488.3
B51: GP Ratio | D51: =D50/D11 -> 0.013645516 | E51: =E50/E11 -> 0.01126723 | G51: =G50/G11 -> 0.013645516 | H51: =H50/H11 -> 0.01126723
B53: Net Profit | D53: =D23 -> 873533.16 | E53: =E23 -> 1469953.2 | G53: =G23 -> 873533.16 | H53: =H23 -> 1469953.2
B54: NP Ratio | D54: =D53/D11 -> 0.0025049454 | E54: =E53/E11 -> 0.0028255156 | G54: =G53/G11 -> 0.0025049454 | H54: =H53/H11 -> 0.0028255156
...

Sheet BS Lia
C1: ='[1]BS Cap'!C1 -> SINGLA STEEL CORPORATION
C2: ='[1]BS Cap'!C2 -> Notes to Financial Statements for the year ended 31.03.2025
B4: =BS!C10 -> 1 | C4: Owners Capital Account | F4: =PL!E5 -> (Amount in INR)
C5: PARTICULARS | E5: =BS!D6 -> As at 31.03.2025 | F5: =BS!E6 -> As at 31.03.2024 | H5: =BS!G6 -> As at 31.03.2025 Amount (Rs.) | I5: =BS!H6 -> As at 31.03.2024 Amount (Rs.)
B6: (a) | C6: =CONCATENATE('My Contect'!D5) -> ASHWANI KUMAR SINGLA
C7: =CONCATENATE("Opening Balance as at ",'My Contect'!E13) -> Opening Balance as at 1st April, 2024 | E7: =F13 -> 12874544 | F7: =I7/'My Contect'!$E$2 -> 13329096 | H7: =I13 -> 12874544 | I7: 13329096
C9: Add / (Less) : Net Change during the year | E9: =H9/'My Contect'!$E$2 -> 1302947.4 | F9: =I9/'My Contect'!$E$2 -> -1924505.2 | H9: ='Trial 2025'!H11-'BS Lia'!H7 -> 1302947.4 | I9: -1924505.2
C11: Add: Share of Profit / Loss for the year | E11: =PL!D30 -> 834683.16 | F11: =PL!E30 -> 1469953.2 | H11: =PL!G30 -> 834683.16 | I11: =PL!H30 -> 1469953.2
C13: =CONCATENATE("Closing Balance as at ",'My Contect'!E14) -> Closing Balance as at 31st March, 2025 | E13: =SUM(E7:E11) -> 15012174 | F13: =SUM(F7:F11) -> 12874544 | G13: =SUM(G7:G11) -> 0 | H13: =SUM(H7:H11) -> 15012174 | I13: =SUM(I7:I11) -> 12874544
B16: =BS!C11 -> 1 | C16: Reserves & Surplus | F16: ='[1]BS Cap'!H4 -> (Amount in INR)
C17: PARTICULARS | E17: =BS!D6 -> As at 31.03.2025 | F17: =BS!E6 -> As at 31.03.2024 | H17: ='[1]BS Cap'!L5 -> As at 31.03.2025 Amount (Rs.) | I17: ='[1]BS Cap'!M5 -> As at 31.03.2024 Amount (Rs.)
B18: (a) | C18: Surplus
C19: Opening Balance | E19: =F22 -> 0 | F19: =I19/'My Contect'!$E$2 -> 0 | H19: =I22 -> 0 | I19: 0
C20: Add: Profit/(Loss) During the year
A21: *
C22: Closing Balance | E22: =SUM(E19:E21) -> 0 | F22: =SUM(F19:F21) -> 0 | H22: =SUM(H19:H21) -> 0 | I22: =SUM(I19:I21) -> 0
B25: =BS!C16 -> 2 | C25: Long-Term Borrowings | F25: =F16 -> (Amount in INR)
C26: PARTICULARS | E26: =E17 -> As at 31.03.2025 | F26: =F17 -> As at 31.03.2024 | H26: =H17 -> As at 31.03.2025 Amount (Rs.) | I26: =I17 -> As at 31.03.2024 Amount (Rs.)
C27: Secured
C28: Term Loans
C29: From Banks
B30: (a) | C30: Term Loan from Central Bank of India | E30: =H30/'My Contect'!$E$2 -> 0 | F30: =I30/'My Contect'!$E$2 -> 0 | I30: 0
C31: ( Secured by Hypothecation of Plant and Machinery, Personal Property of Director at Ludhiana along with Personal Guarantee of Directors )
C33: Unsecured
B34: (a) | C34: Loans and advances from Related Parties | E34: =H34/'My Contect'!$E$2 -> 19187969 | F34: =I34/'My Contect'!$E$2 -> 38624774 | H34: =Sheet4!C23 -> 19187969 | I34: =Sheet4!D23 -> 38624774
C35: Loans repayable in 2024-25 | E35: =H35/'My Contect'!$E$2 -> 0 | F35: =I35/'My Contect'!$E$2 -> 0
C37: Total | E37: =SUM(E30:E36) -> 19187969 | F37: =SUM(F30:F36) -> 38624774 | H37: =SUM(H30:H36) -> 19187969 | I37: =SUM(I30:I36) -> 38624774
C41: ='[1]BS Cap (2)'!C23 -> (CA. KESHAV GUPTA) | E41: =BS!C57 -> ASHWANI KUMAR SINGLA
C42: ='[1]BS Cap'!C53 -> AUDITOR | E42: =BS!C58 -> PROPRIETOR
C44: =C1 -> SINGLA STEEL CORPORATION
C45: =C2 -> Notes to Financial Statements for the year ended 31.03.2025
B47: =BS!C22 -> 3 | C47: Short-Term Borrowings | F47: =F25 -> (Amount in INR)
C48: PARTICULARS | E48: =E26 -> As at 31.03.2025 | F48: =F26 -> As at 31.03.2024 | H48: =H26 -> As at 31.03.2025 Amount (Rs.) | I48: =I26 -> As at 31.03.2024 Amount (Rs.)
B49: 1 | C49: Secured
B50: (a) | C50: OD Limit (From Banks)
C51: - HDFC Bank Limited | E51: =H51/'My Contect'!$E$2 -> 9407706 | F51: =I51/'My Contect'!$E$2 -> 7180440.6 | H51: =Sheet4!C11 -> 9407706 | I51: =Sheet4!D11 -> 7180440.6
C52: ( Secured by Hypothecation of Stock and Receivable at all present and future location of the firm )
B54: (b) | C54: Current Maturities of Long-term Borrowings | E54: =H54/'My Contect'!$E$2 -> 0 | F54: =I54/'My Contect'!$E$2 -> 0
B56: 2 | C56: Unsecured
C57: From Related Parties
...

Sheet FA NEW
C1: ='BS Lia'!C1 -> SINGLA STEEL CORPORATION
C2: ='BS Lia'!C2 -> Notes to Financial Statements for the year ended 31.03.2025
B4: =BS!C31 -> 7 | C4: Property , Plant & Equipment
B5: Sr No | C5: PARTICULARS | D5: WDV AS AT 01.04.2024 | E5: ADDITIONS DURING THE YEAR (USED FOR MORE THAN 180 DAYS | F5: ADDITIONS DURING THE YEAR (USED FOR LESS THAN 180 DAYS | G5: SALE / ADJ. DURING THE YEAR | H5: TOTAL | I5: RATE OF DEPRECIATION | J5: DEPRECIATION PROVIDED FOR THE YEAR | K5: WDV AS AT 31.03.2025
C9: i) Tangible Assets
B10: 1 | C10: FURNITURE & FIXTURES | D10: =SUMIFS('[1]FAR 2025'!L:L,'[1]FAR 2025'!F:F,'FA NEW'!C10) -> 19672 | E10: =SUMIFS('[1]FAR 2025'!M:M,'[1]FAR 2025'!F:F,'FA NEW'!C10,'[1]FAR 2025'!J:J,">180") -> 0 | F10: =SUMIFS('[1]FAR 2025'!M:M,'[1]FAR 2025'!F:F,'FA NEW'!C10,'[1]FAR 2025'!J:J,"<=180") -> 0 | G10: =SUMIFS('[1]FAR 2025'!N:N,'[1]FAR 2025'!F:F,'FA NEW'!C10) -> 0 | H10: =D10+E10+F10-G10 -> 19672 | I10: 0.1 | J10: =SUMIFS('[1]FAR 2025'!S:S,'[1]FAR 2025'!F:F,'FA NEW'!C47) -> 1968 | K10: =H10-J10 -> 17704 | M10: =ROUND(D10*I10,0)-J10 -> -1
B12: =B10+1 -> 2 | C12: OFFICE EQUIPMENTS | D12: =SUMIFS('[1]FAR 2025'!L:L,'[1]FAR 2025'!F:F,'FA NEW'!C12) -> 308521 | E12: =SUMIFS('[1]FAR 2025'!M:M,'[1]FAR 2025'!F:F,'FA NEW'!C12,'[1]FAR 2025'!J:J,">180") -> 0 | F12: =SUMIFS('[1]FAR 2025'!M:M,'[1]FAR 2025'!F:F,'FA NEW'!C12,'[1]FAR 2025'!J:J,"<=180") -> 2667.16 | G12: =SUMIFS('[1]FAR 2025'!N:N,'[1]FAR 2025'!F:F,'FA NEW'!C12) -> 0 | H12: =D12+E12+F12-G12 -> 311188.16 | I12: 0.15 | J12: =SUMIFS('[1]FAR 2025'!S:S,'[1]FAR 2025'!F:F,'FA NEW'!C49) -> 46477.16 | K12: =H12-J12 -> 264711 | M12: =ROUND(D12*I12,0)-J12 -> -199.16
B14: =+B12+1 -> 3 | C14: MACHINERY | D14: =SUMIFS('[1]FAR 2025'!L:L,'[1]FAR 2025'!F:F,'FA NEW'!C14) -> 412182 | E14: =SUMIFS('[1]FAR 2025'!M:M,'[1]FAR 2025'!F:F,'FA NEW'!C14,'[1]FAR 2025'!J:J,">180") -> 0 | F14: =SUMIFS('[1]FAR 2025'!M:M,'[1]FAR 2025'!F:F,'FA NEW'!C14,'[1]FAR 2025'!J:J,"<=180") -> 0 | G14: =SUMIFS('[1]FAR 2025'!N:N,'[1]FAR 2025'!F:F,'FA NEW'!C14) -> 0 | H14: =D14+E14+F14-G14 -> 412182 | I14: 0.15 | J14: =SUMIFS('[1]FAR 2025'!S:S,'[1]FAR 2025'!F:F,'FA NEW'!C51) -> 61827 | K14: =H14-J14 -> 350355 | M14: =ROUND(D14*I14,0)-J14 -> 0
B16: =+B14+1 -> 4 | C16: COMPUTER | D16: =SUMIFS('[1]FAR 2025'!L:L,'[1]FAR 2025'!F:F,'FA NEW'!C16) -> 1090 | E16: =SUMIFS('[1]FAR 2025'!M:M,'[1]FAR 2025'!F:F,'FA NEW'!C16,'[1]FAR 2025'!J:J,">180") -> 0 | F16: =SUMIFS('[1]FAR 2025'!M:M,'[1]FAR 2025'!F:F,'FA NEW'!C16,'[1]FAR 2025'!J:J,"<=180") -> 0 | G16: =SUMIFS('[1]FAR 2025'!N:N,'[1]FAR 2025'!F:F,'FA NEW'!C16) -> 0 | H16: =D16+E16+F16-G16 -> 1090 | I16: 0.4 | J16: =SUMIFS('[1]FAR 2025'!S:S,'[1]FAR 2025'!F:F,'FA NEW'!C53) -> 436 | K16: =H16-J16 -> 654 | M16: =ROUND(D16*I16,0)-J16 -> 0
B18: =B16+1 -> 5 | C18: VEHICLES | D18: =SUMIFS('[1]FAR 2025'!L:L,'[1]FAR 2025'!F:F,'FA NEW'!C18) -> 426592 | E18: =SUMIFS('[1]FAR 2025'!M:M,'[1]FAR 2025'!F:F,'FA NEW'!C18,'[1]FAR 2025'!J:J,">180") -> 0 | F18: =SUMIFS('[1]FAR 2025'!M:M,'[1]FAR 2025'!F:F,'FA NEW'!C18,'[1]FAR 2025'!J:J,"<=180") -> 0 | G18: =SUMIFS('[1]FAR 2025'!N:N,'[1]FAR 2025'!F:F,'FA NEW'!C18) -> 0 | H18: =D18+E18+F18-G18 -> 426592 | I18: 0.15 | J18: =SUMIFS('[1]FAR 2025'!S:S,'[1]FAR 2025'!F:F,'FA NEW'!C55) -> 63989 | K18: =H18-J18 -> 362603 | M18: =ROUND(D18*I18,0)-J18 -> 0
B20: =B18+1 -> 6 | D20: =K57 -> 0 | H20: =D20+E20+F20-G20 -> 0 | I20: 0.4 | J20: =SUMIFS('[1]FAR 2025'!S:S,'[1]FAR 2025'!F:F,'FA NEW'!C57) -> 0 | K20: =H20-J20 -> 0
C22: TOTAL | D22: =SUM(D10:D21) -> 1168057 | E22: =SUM(E10:E21) -> 0 | F22: =SUM(F10:F21) -> 2667.16 | H22: =SUM(H10:H21) -> 1170724.2 | J22: =SUM(J10:J21) -> 174697.16 | K22: =SUM(K10:K21) -> 996027 | M22: 1169667.2 | N22: =H22-M22 -> 1057
C24: Ii) Intangible Assets
B25: 1 | C25: COMPUTER SOFTWARE | H25: =+D25+E25-F25-G25 -> 0 | K25: =H25-J25 -> 0
B27: =B25+1 -> 2 | C27: TRADEMARKS | H27: =+D27+E27-F27-G27 -> 0 | K27: =H27-J27 -> 0
C29: PREVIOUS YEAR | D29: =-D59 -> -759835 | E29: =-E59 -> -499090.65 | F29: =-F59 -> -105221.88 | G29: =-G59 -> 0 | H29: =-H59 -> -1364147.5 | J29: =-J59 -> -196090.53 | K29: =-K59 -> -1168057
C36: ='BS Lia'!C122 -> (CA. KESHAV GUPTA) | H36: ='BS Lia'!E122 -> ASHWANI KUMAR SINGLA
C37: ='BS Lia'!C123 -> AUDITOR | H37: ='BS Lia'!E123 -> PROPRIETOR
B41: =BS!C31 -> 7 | C41: Property , Plant & Equipment
B42: Sr No | C42: PARTICULARS | D42: WDV AS AT 01.04.2022 | E42: ADDITIONS DURING THE YEAR (USED FOR MORE THAN 180 DAYS | F42: ADDITIONS DURING THE YEAR (USED FOR LESS THAN 180 DAYS | G42: SALE / ADJ. DURING THE YEAR | H42: =H91 -> 0 | I42: RATE OF DEPRECIATION | J42: DEPRECIATION PROVIDED FOR THE YEAR | K42: WDV AS AT 31.03.2023
C46: i) Tangible Assets
A47: = | B47: 1 | C47: FURNITURE & FIXTURES | D47: =SUMIFS('[1]FAR 2024'!L:L,'[1]FAR 2024'!F:F,'FA NEW'!C47) -> 21857 | E47: =SUMIFS('[1]FAR 2024'!M:M,'[1]FAR 2024'!F:F,'FA NEW'!C47,'[1]FAR 2024'!J:J,">180") -> 0 | F47: =SUMIFS('[1]FAR 2024'!M:M,'[1]FAR 2024'!F:F,'FA NEW'!C47,'[1]FAR 2024'!J:J,"<=180") -> 0 | G47: =SUMIFS('[1]FAR 2024'!N:N,'[1]FAR 2024'!F:F,'FA NEW'!C47) -> 0 | H47: =+D47+E47+F47-G47 -> 21857 | I47: 0.1 | J47: =SUMIFS('[1]FAR 2024'!S:S,'[1]FAR 2024'!F:F,'FA NEW'!C47) -> 2185 | K47: =H47-J47 -> 19672 | M47: 2185 | N47: =J47-M47 -> 0
B49: =B47+1 -> 2 | C49: OFFICE EQUIPMENTS | D49: =SUMIFS('[1]FAR 2024'!L:L,'[1]FAR 2024'!F:F,'FA NEW'!C49) -> 237887 | E49: =SUMIFS('[1]FAR 2024'!M:M,'[1]FAR 2024'!F:F,'FA NEW'!C49,'[1]FAR 2024'!J:J,">180") -> 99090.65 | F49: =SUMIFS('[1]FAR 2024'!M:M,'[1]FAR 2024'!F:F,'FA NEW'!C49,'[1]FAR 2024'!J:J,"<=180") -> 23881.24 | G49: =SUMIFS('[1]FAR 2024'!N:N,'[1]FAR 2024'!F:F,'FA NEW'!C49) -> 0 | H49: =+D49+E49+F49-G49 -> 360858.89 | I49: 0.15 | J49: =SUMIFS('[1]FAR 2024'!S:S,'[1]FAR 2024'!F:F,'FA NEW'!C49) -> 52337.89 | K49: =H49-J49 -> 308521 | M49: 52337.89 | N49: =J49-M49 -> 0
B51: =+B49+1 -> 3 | C51: MACHINERY | D51: =SUMIFS('[1]FAR 2024'!L:L,'[1]FAR 2024'!F:F,'FA NEW'!C51) -> 84920 | E51: =SUMIFS('[1]FAR 2024'!M:M,'[1]FAR 2024'!F:F,'FA NEW'!C51,'[1]FAR 2024'!J:J,">180") -> 400000 | F51: =SUMIFS('[1]FAR 2024'!M:M,'[1]FAR 2024'!F:F,'FA NEW'!C51,'[1]FAR 2024'!J:J,"<=180") -> 0 | G51: =SUMIFS('[1]FAR 2024'!N:N,'[1]FAR 2024'!F:F,'FA NEW'!C51) -> 0 | H51: =+D51+E51+F51-G51 -> 484920 | I51: 0.15 | J51: =SUMIFS('[1]FAR 2024'!S:S,'[1]FAR 2024'!F:F,'FA NEW'!C51) -> 72738 | K51: =H51-J51 -> 412182 | M51: 72738 | N51: =J51-M51 -> 0
B53: =B51+1 -> 4 | C53: COMPUTER | D53: =SUMIFS('[1]FAR 2024'!L:L,'[1]FAR 2024'!F:F,'FA NEW'!C53) -> 1816 | E53: =SUMIFS('[1]FAR 2024'!M:M,'[1]FAR 2024'!F:F,'FA NEW'!C53,'[1]FAR 2024'!J:J,">180") -> 0 | F53: =SUMIFS('[1]FAR 2024'!M:M,'[1]FAR 2024'!F:F,'FA NEW'!C53,'[1]FAR 2024'!J:J,"<=180") -> 0 | G53: =SUMIFS('[1]FAR 2024'!N:N,'[1]FAR 2024'!F:F,'FA NEW'!C53) -> 0 | H53: =+D53+E53+F53-G53 -> 1816 | I53: 0.4 | J53: =SUMIFS('[1]FAR 2024'!S:S,'[1]FAR 2024'!F:F,'FA NEW'!C53) -> 726 | K53: =H53-J53 -> 1090 | M53: 726 | N53: =J53-M53 -> 0
B55: 5 | C55: VEHICLES | D55: =SUMIFS('[1]FAR 2024'!L:L,'[1]FAR 2024'!F:F,'FA NEW'!C55) -> 413355 | E55: =SUMIFS('[1]FAR 2024'!M:M,'[1]FAR 2024'!F:F,'FA NEW'!C55,'[1]FAR 2024'!J:J,">180") -> 0 | F55: =SUMIFS('[1]FAR 2024'!M:M,'[1]FAR 2024'!F:F,'FA NEW'!C55,'[1]FAR 2024'!J:J,"<=180") -> 81340.64 | G55: =SUMIFS('[1]FAR 2024'!N:N,'[1]FAR 2024'!F:F,'FA NEW'!C55) -> 0 | H55: =+D55+E55+F55-G55 -> 494695.64 | I55: 0.15 | J55: =SUMIFS('[1]FAR 2024'!S:S,'[1]FAR 2024'!F:F,'FA NEW'!C55) -> 68103.64 | K55: =H55-J55 -> 426592 | M55: 68103.64 | N55: =J55-M55 -> 0
B57: =+B55+1 -> 6 | D57: =SUMIFS('[1]FAR 2024'!L:L,'[1]FAR 2024'!F:F,'FA NEW'!C57) -> 0 | E57: =SUMIFS('[1]FAR 2024'!M:M,'[1]FAR 2024'!F:F,'FA NEW'!C57,'[1]FAR 2024'!J:J,">180") -> 0 | F57: =SUMIFS('[1]FAR 2024'!M:M,'[1]FAR 2024'!F:F,'FA NEW'!C57,'[1]FAR 2024'!J:J,"<=180") -> 0 | G57: =SUMIFS('[1]FAR 2024'!N:N,'[1]FAR 2024'!F:F,'FA NEW'!C57) -> 0 | H57: =+D57+E57+F57-G57 -> 0 | I57: 0.4 | J57: =ROUND((((D57-G57+E57)*I57)+((F57/2)*I57)),0) -> 0 | K57: =H57-J57 -> 0
M58: 196090.53 | N58: =J59-M58 -> 0
C59: TOTAL | D59: =SUM(D47:D58) -> 759835 | E59: =SUM(E47:E58) -> 499090.65 | F59: =SUM(F47:F58) -> 105221.88 | G59: =SUM(G47:G58) -> 0 | H59: =SUM(H47:H58) -> 1364147.5 | J59: =SUM(J47:J58) -> 196090.53 | K59: =SUM(K47:K58) -> 1168057 | M59: ='[1]FAR 2024'!S53 -> 196090.53 | N59: =J59-M59 -> 0
C61: Ii) Intangible Assets
B62: 1 | C62: COMPUTER SOFTWARE | H62: =+D62+E62-F62 -> 0
B64: =B62+1 -> 2 | C64: TRADEMARKS | H64: =+D64+E64-F64 -> 0
C66: PREVIOUS YEAR | D66: =D108/10^5 -> 0 | E66: =E108/10^5 -> 0 | F66: =F108/10^5 -> 0 | H66: =+D66+E66-F66 -> 0 | J66: =K108/10^5 -> 0 | K66: =+H66-#REF! -> #REF!
C72: ='BS Lia'!C122 -> (CA. KESHAV GUPTA) | J72: ='BS Lia'!E122 -> ASHWANI KUMAR SINGLA
C73: ='BS Lia'!C123 -> AUDITOR | J73: ='BS Lia'!E123 -> PROPRIETOR

Sheet BS Assets
C1: ='BS Lia'!C1 -> SINGLA STEEL CORPORATION
C2: ='BS Lia'!C2 -> Notes to Financial Statements for the year ended 31.03.2025
B4: =+BS!C33 -> 7 | C4: Non-Current Investments | F4: ='BS Lia'!F16 -> (Amount in INR)
C5: PARTICULARS | E5: =BS!D6 -> As at 31.03.2025 | F5: =BS!E6 -> As at 31.03.2024 | H5: =BS!G6 -> As at 31.03.2025 Amount (Rs.) | I5: =BS!H6 -> As at 31.03.2024 Amount (Rs.)
B7: (a) | C7: Investment in Gold | E7: =H7/'My Contect'!$E$2 -> 0 | F7: =I7/'My Contect'!$E$2 -> 0 | H7: ='Trial 2025'!G74 -> 0 | I7: ='Trial 2025'!I74 -> 0
C9: Total | E9: =SUM(E7:E8) -> 0 | F9: =SUM(F7:F8) -> 0 | H9: =SUM(H7:H8) -> 0 | I9: =SUM(I7:I8) -> 0
B12: =+BS!C34 -> 7 | C12: Deferred Tax Assets (Net) | F12: ='BS Lia'!F16 -> (Amount in INR)
C13: PARTICULARS | E13: =BS!D6 -> As at 31.03.2025 | F13: =BS!E6 -> As at 31.03.2024 | H13: ='BS Lia'!H17 -> As at 31.03.2025 Amount (Rs.) | I13: ='BS Lia'!I17 -> As at 31.03.2024 Amount (Rs.)
C14: Deferred tax asset
B15: (a) | C15: Related to Property, Plant & Equipments | E15: =H15/'My Contect'!$E$2 -> 0 | F15: =I15/'My Contect'!$E$2 -> 0 | H15: ='[1]DTA 2022'!H18 -> 0 | I15: 0
B16: (b) | C16: Related to Pre-incorporation Expenses | E16: =H16/'My Contect'!$E$2 -> 0 | F16: =I16/'My Contect'!$E$2 -> 0 | H16: ='[1]DTA 2022'!H22 -> 0 | I16: 0
C18: Total | E18: =SUM(E15:E17) -> 0 | F18: =SUM(F15:F17) -> 0 | H18: =SUM(H15:H17) -> 0 | I18: =SUM(I15:I17) -> 0
B21: =BS!C36 -> 7 | C21: Other Non Current Assets | F21: =F12 -> (Amount in INR)
C22: PARTICULARS | E22: =E13 -> As at 31.03.2025 | F22: =F13 -> As at 31.03.2024 | H22: =H13 -> As at 31.03.2025 Amount (Rs.) | I22: =I13 -> As at 31.03.2024 Amount (Rs.)
B24: (a) | C24: Security Deposits | E24: =H24/'My Contect'!$E$2 -> 0 | F24: =I24/'My Contect'!$E$2 -> 0 | H24: ='Trial 2025'!G76 -> 0 | I24: ='Trial 2025'!I76 -> 0
C26: Total | E26: =SUM(E23:E25) -> 0 | F26: =SUM(F23:F25) -> 0 | H26: =SUM(H23:H25) -> 0 | I26: =SUM(I23:I25) -> 0
B29: =+BS!C39 -> 8 | C29: Inventories | F29: =F21 -> (Amount in INR)
C30: PARTICULARS | E30: =E22 -> As at 31.03.2025 | F30: =F22 -> As at 31.03.2024 | H30: =H22 -> As at 31.03.2025 Amount (Rs.) | I30: =I22 -> As at 31.03.2024 Amount (Rs.)
B32: (a) | C32: Raw Material | E32: =H32/'My Contect'!$E$2 -> 0 | F32: =I32/'My Contect'!$E$2 -> 0 | H32: 0 | I32: 0
B33: (b) | C33: Work-in-Progress | E33: =H33/'My Contect'!$E$2 -> 0 | F33: =I33/'My Contect'!$E$2 -> 0 | H33: ='PL Det'!G46 -> 0 | I33: ='PL Det'!H46 -> 0
B34: (c) | C34: Finished Goods | E34: =H34/'My Contect'!$E$2 -> 0 | F34: =I34/'My Contect'!$E$2 -> 0 | H34: ='PL Det'!G47 -> 0 | I34: ='PL Det'!H47 -> 0
B35: (a) | C35: Stock-in-Trade | E35: =H35/'My Contect'!$E$2 -> 954550 | F35: =I35/'My Contect'!$E$2 -> 3580000 | H35: ='PL Det'!G48 -> 954550 | I35: ='PL Det'!H48 -> 3580000
C37: Total | E37: =SUM(E32:E36) -> 954550 | F37: =SUM(F32:F36) -> 3580000 | H37: =SUM(H32:H36) -> 954550 | I37: =SUM(I32:I36) -> 3580000
B40: =+BS!C40 -> 9 | C40: Trade Receivables | F40: =F29 -> (Amount in INR)
C41: PARTICULARS | E41: =E30 -> As at 31.03.2025 | F41: =F30 -> As at 31.03.2024 | H41: =H30 -> As at 31.03.2025 Amount (Rs.) | I41: =I30 -> As at 31.03.2024 Amount (Rs.)
B42: 1 | C42: Unsecured, Considered Good
B43: (a) | C43: Trade Receivables | E43: =H43/'My Contect'!$E$2 -> 54524240 | F43: =I43/'My Contect'!$E$2 -> 70762062 | H43: =Sheet4!C120 -> 54524240 | I43: =Sheet4!D120 -> 70762062
C44: =CONCATENATE("( For Trade Receivables aging schedule Refer Note No. ",'Aging Analysis'!B29," )") -> ( For Trade Receivables aging schedule Refer Note No. 22 )
C46: Total | E46: =SUM(E43:E44) -> 54524240 | F46: =SUM(F43:F44) -> 70762062 | H46: =SUM(H43:H44) -> 54524240 | I46: =SUM(I43:I44) -> 70762062
C53: ='FA NEW'!C36 -> (CA. KESHAV GUPTA) | E53: ='BS Lia'!E122 -> ASHWANI KUMAR SINGLA | F53: ='BS Lia'!F122 -> 0 | H53: =E53 -> ASHWANI KUMAR SINGLA
C54: ='FA NEW'!C37 -> AUDITOR | E54: ='BS Lia'!E123 -> PROPRIETOR | F54: ='BS Lia'!F123 -> 0 | H54: =E54 -> PROPRIETOR
C56: =C1 -> SINGLA STEEL CORPORATION
C57: =C2 -> Notes to Financial Statements for the year ended 31.03.2025
B59: =+BS!C41 -> 10 | C59: Cash and Bank Balances | F59: =F40 -> (Amount in INR)
C60: PARTICULARS | E60: =E30 -> As at 31.03.2025 | F60: =F30 -> As at 31.03.2024 | H60: =H30 -> As at 31.03.2025 Amount (Rs.) | I60: =I30 -> As at 31.03.2024 Amount (Rs.)
B61: 1 | C61: Cash & Cash Equivalents
B62: (a) | C62: Balances with banks | E62: =H62/'My Contect'!$E$2 -> 0 | F62: =I62/'My Contect'!$E$2 -> 0 | H62: ='Trial 2025'!G160+'Trial 2025'!G161 -> 0 | I62: ='Trial 2025'!I160 -> 0
B63: (a) | C63: Cheques-in-Hand | E63: =H63/'My Contect'!$E$2 -> 403049 | F63: =I63/'My Contect'!$E$2 -> 310684 | H63: ='Trial 2025'!G158 -> 403049 | I63: ='Trial 2025'!I158 -> 310684
B64: (b) | C64: Cash on hand | E64: =H64/'My Contect'!$E$2 -> 255827 | F64: =I64/'My Contect'!$E$2 -> 141840 | H64: =SUM('Trial 2025'!G157:G157) -> 255827 | I64: ='Trial 2025'!I157 -> 141840
E66: =SUM(E62:E65) -> 658876 | F66: =SUM(F62:F65) -> 452524 | H66: =SUM(H62:H65) -> 658876 | I66: =SUM(I62:I65) -> 452524
...

Sheet PL Det
C1: ='BS Assets'!C1 -> SINGLA STEEL CORPORATION
C2: ='BS Assets'!C2 -> Notes to Financial Statements for the year ended 31.03.2025
B4: =+PL!C8 -> 12 | C4: Revenue from Operations | E4: ='BS Assets'!F12 -> (Amount in INR)
C5: PARTICULARS | D5: =PL!D6 -> For the year ended 31.03.2025 | E5: =PL!E6 -> For the year ended 31.03.2024 | G5: =PL!G6 -> For the year ended 31.03.2025 Amount (Rs.) | H5: =PL!H6 -> For the year ended 31.03.2024 Amount (Rs.)
B7: (a) | C7: Sale of products | D7: =G7/'My Contect'!$E$2 -> 3.4871796e+08 | E7: =H7/'My Contect'!$E$2 -> 520171626 | G7: =SUMIFS('Trial 2025'!H:H,'Trial 2025'!A:A,'PL Det'!C7) -> 3.4871796e+08 | H7: 520171626
C9: Total | D9: =SUM(D7:D8) -> 3.4871796e+08 | E9: =SUM(E7:E8) -> 520171626 | G9: =SUM(G7:G8) -> 3.4871796e+08 | H9: =SUM(H7:H8) -> 520171626 | J9: =G9-'Trial 2025'!H173 -> 0 | K9: shall be zero
B12: =+PL!C9 -> 13 | C12: Other Income | E12: =E4 -> (Amount in INR)
C13: PARTICULARS | D13: =D5 -> For the year ended 31.03.2025 | E13: =E5 -> For the year ended 31.03.2024 | G13: =G5 -> For the year ended 31.03.2025 Amount (Rs.) | H13: =H5 -> For the year ended 31.03.2024 Amount (Rs.)
B14: (a) | C14: Interest Income | D14: =G14/'My Contect'!$E$2 -> 5483 | E14: =H14/'My Contect'!$E$2 -> 70853 | G14: =SUMIFS('Trial 2025'!H:H,'Trial 2025'!A:A,'PL Det'!C14) -> 5483 | H14: 70853
B15: (b) | C15: Rebate & Discount | D15: =G15/'My Contect'!$E$2 -> 0 | E15: =H15/'My Contect'!$E$2 -> 0 | G15: =SUMIFS('Trial 2025'!H:H,'Trial 2025'!A:A,'PL Det'!C15) -> 0
B16: (c) | C16: Foreign Exchange Gain | D16: =G16/'My Contect'!$E$2 -> 0 | E16: =H16/'My Contect'!$E$2 -> 0 | G16: =SUMIFS('Trial 2025'!H:H,'Trial 2025'!A:A,'PL Det'!C16) -> 0
C18: Total | D18: =SUM(D14:D17) -> 5483 | E18: =SUM(E14:E17) -> 70853 | G18: =SUM(G14:G17) -> 5483 | H18: =SUM(H14:H17) -> 70853
B21: =PL!C13 -> 13 | C21: Cost of materials consumed | E21: =E12 -> (Amount in INR)
C22: PARTICULARS | D22: =D13 -> For the year ended 31.03.2025 | E22: =E13 -> For the year ended 31.03.2024 | G22: =G13 -> For the year ended 31.03.2025 Amount (Rs.) | H22: =H13 -> For the year ended 31.03.2024 Amount (Rs.)
B24: (a) | C24: Purchase of Raw Material | D24: =G24/'My Contect'!$E$2 -> 0 | E24: =H24/'My Contect'!$E$2 -> 0 | G24: =SUMIFS('Trial 2025'!G:G,'Trial 2025'!A:A,'PL Det'!C24) -> 0 | H24: =SUMIFS('Trial 2025'!I:I,'Trial 2025'!A:A,'PL Det'!C24) -> 0
C26: Total | D26: =SUM(D24:D25) -> 0 | E26: =SUM(E24:E25) -> 0 | G26: =SUM(G24:G25) -> 0 | H26: =SUM(H24:H25) -> 0
B28: =PL!C14 -> 14 | C28: Purchases of Stock-in-Trade | E28: =E21 -> (Amount in INR)
C29: PARTICULARS | D29: =D22 -> For the year ended 31.03.2025 | E29: =E22 -> For the year ended 31.03.2024 | G29: =G22 -> For the year ended 31.03.2025 Amount (Rs.) | H29: =H22 -> For the year ended 31.03.2024 Amount (Rs.)
B31: (a) | C31: Purchase of products | D31: =G31/'My Contect'!$E$2 -> 3.4096129e+08 | E31: =H31/'My Contect'!$E$2 -> 5.1095658e+08 | G31: =SUMIFS('Trial 2025'!G:G,'Trial 2025'!A:A,'PL Det'!C31) -> 3.4096129e+08 | H31: 5.1095658e+08
B32: (b) | C32: Freight and Cartage Inward | D32: =G32/'My Contect'!$E$2 -> 372706 | E32: =H32/'My Contect'!$E$2 -> 792778 | G32: =SUMIFS('Trial 2025'!G:G,'Trial 2025'!A:A,'PL Det'!C32) -> 372706 | H32: 792778
C34: Total | D34: =SUM(D30:D32) -> 3.4133399e+08 | E34: =SUM(E30:E32) -> 5.1174936e+08 | G34: =SUM(G30:G32) -> 3.4133399e+08 | H34: =SUM(H30:H32) -> 5.1174936e+08
B37: =+PL!C15 -> 15 | C37: =PL!B15 -> Changes in Inventories of Finished Goods, Work-in-Progress and Stock-in-Trade
E38: =E21 -> (Amount in INR)
C39: PARTICULARS | D39: =D13 -> For the year ended 31.03.2025 | E39: =E13 -> For the year ended 31.03.2024 | G39: =G13 -> For the year ended 31.03.2025 Amount (Rs.) | H39: =H13 -> For the year ended 31.03.2024 Amount (Rs.)
C40: Opening Stock
C41: Work-in-Progress | D41: =G41/'My Contect'!$E$2 -> 0 | E41: 0 | G41: =H46 -> 0
C42: Finished Goods | D42: =G42/'My Contect'!$E$2 -> 0 | E42: =H42/'My Contect'!$E$2 -> 0 | G42: =H47 -> 0 | H42: 0
C43: Stock-in-Trade | D43: =G43/'My Contect'!$E$2 -> 3580000 | E43: =H43/'My Contect'!$E$2 -> 6140576 | G43: =H48 -> 3580000 | H43: ='Trial 2025'!I78 -> 6140576
C45: Less : Closing Stock
C46: Work-in-Progress | D46: =G46/'My Contect'!$E$2 -> 0 | E46: =H46/'My Contect'!$E$2 -> 0 | G46: =G56 -> 0
C47: Finished Goods | D47: =G47/'My Contect'!$E$2 -> 0 | E47: =H47/'My Contect'!$E$2 -> 0 | G47: =G60 -> 0
C48: Stock-in-Trade | D48: =G48/'My Contect'!$E$2 -> 954550 | E48: =H48/'My Contect'!$E$2 -> 3580000 | G48: =12060*(39.15+40)+1 -> 954550 | H48: 3580000
C50: Total | D50: =SUM(D41:D43)-SUM(D46:D48) -> 2625450 | E50: =SUM(E41:E43)-SUM(E46:E48) -> 2560576 | F50: =SUM(F70:F76) -> 0 | G50: =SUM(G41:G43)-SUM(G46:G48) -> 2625450 | H50: =SUM(H41:H43)-SUM(H46:H48) -> 2560576
C52: Details of Inventroy:
C53: Work-in-Progress
C54: -Yarn | D54: =G54/'My Contect'!$E$2 -> 0 | E54: =H54/'My Contect'!$E$2 -> 0 | G54: 0
C55: -Fibre
C56: Total | D56: =SUM(D54:D55) -> 0 | E56: =SUM(E54:E55) -> 0 | F56: =SUM(F76:F76) -> 0 | G56: =SUM(G54:G55) -> 0 | H56: =SUM(H54:H55) -> 0
C57: Finished Goods
C58: -Yarn | D58: =G58/'My Contect'!$E$2 -> 0 | E58: =H58/'My Contect'!$E$2 -> 0
...

Sheet Aging Analysis
C1: =[1]Ratio!C1 -> SINGLA STEEL CORPORATION
C2: =[1]Ratio!C2 -> Notes to Financial Statements for the year ended 31.03.2025
B4: ='PL Det'!B116+1 -> 20 | C4: Based upon the intimation received from the suppliers, principal amount unpaid to such suppliers who qualify under the definition of micro and small enterprises, as under Micro, Small and Medium Development, 2006 as at 31st March,2024 are as follows;
I5: =[1]Ratio!G4 -> (Amount in INR)
C6: Particulars | H6: ='BS Lia'!E80 -> As at 31.03.2025 | I6: ='BS Lia'!F80 -> As at 31.03.2024
B8: a | C8: Principal Amount remaining unpaid but not due as at the year end. | H8: ='BS Lia'!E82 -> 0 | I8: ='BS Lia'!F82 -> 0
B9: b | C9: Interest due thereon and remaining unpaid as at the year end | H9: 0 | I9: 0
B10: c | C10: Interest paid by the Company in terms of Section 16 of Micro, Small & Medium Enterprises Development Act 2006 along with the amount of payment made to the supplier beyond the appointed day during the year | H10: 0 | I10: 0
B11: d | C11: Interest due and payable for the period of delay in making payment (which have been paid but beyond the appointed day during the year) but without adding the interest specified under Micro, Small and Medium Enterprises Development Act, 2006 | H11: 0 | I11: 0
B12: e | C12: Interest accrued and remaining unpaid as at the year end | H12: 0 | I12: 0
B13: f | C13: Further interest remaining due and payable even in the succeeding year, until such date when the interest dues as above are actually paid to the small enterprises, for the purpose of disallowance of a deductible expenditure under section 23 of the Micro, Small and Medium Enterprises Development Act, 2006. | H13: 0 | I13: 0
B17: ='Aging Analysis'!B4+1 -> 21 | C17: Trade Payables ageing schedule | I17: =I5 -> (Amount in INR)
B18: Sr. No. | C18: Particulars | E18: Outstanding for following periods from due date of payment
E19: Less than 1 year | F19: 1-2 years | G19: 2-3 years | H19: More than 3 years | I19: Total
C20: Undisputed Trade Payables
B21: (i) | C21: MSME | I21: =SUM(E21:H21) -> 0
B22: (ii) | C22: Others | E22: =Sheet4!E45/'My Contect'!$E$2 -> 1754373 | F22: =Sheet4!F45/'My Contect'!$E$2 -> 0 | G22: =Sheet4!G45/'My Contect'!$E$2 -> 0 | H22: =Sheet4!H45/'My Contect'!$E$2 -> 14091843 | I22: =SUM(E22:H22) -> 15846216
C23: Disputed Trade Payables
B24: (i) | C24: MSME | I24: =SUM(E24:H24) -> 0
B25: (ii) | C25: Others | I25: =SUM(E25:H25) -> 0
C26: Total | E26: =SUM(E20:E25) -> 1754373 | F26: =SUM(F20:F25) -> 0 | G26: =SUM(G20:G25) -> 0 | H26: =SUM(H20:H25) -> 14091843 | I26: =SUM(I20:I25) -> 15846216 | J26: =BS!G23-'Aging Analysis'!I26 -> 0
B29: =B17+1 -> 22 | C29: Trade Receivables ageing schedule | I29: =I17 -> (Amount in INR)
B30: Sr. No. | C30: Particulars | D30: Outstanding for following periods from due date of payment
D31: Less than 6 months | E31: 6 months -1 year | F31: 1-2 years | G31: 2-3 years | H31: More than 3 years | I31: Total
C32: Unsecured
B33: (i) | C33: Undisputed Trade receivables
C34: considered good | D34: =Sheet4!E120/'My Contect'!$E$2 -> 52864359 | E34: =Sheet4!F120/'My Contect'!$E$2 -> 0 | F34: =Sheet4!G120/'My Contect'!$E$2 -> 162673 | G34: =Sheet4!H120/'My Contect'!$E$2 -> 535396.5 | H34: =Sheet4!I120/'My Contect'!$E$2 -> 961811 | I34: =SUM(D34:H34) -> 54524240
C35: considered doubtful | I35: =SUM(D35:H35) -> 0
B36: (ii) | C36: Disputed Trade Receivables
C37: considered good | I37: =SUM(D37:H37) -> 0
C38: considered doubtful | I38: =SUM(D38:H38) -> 0
C39: Total | D39: =SUM(D32:D38) -> 52864359 | E39: =SUM(E32:E38) -> 0 | F39: =SUM(F32:F38) -> 162673 | G39: =SUM(G32:G38) -> 535396.5 | H39: =SUM(H32:H38) -> 961811 | I39: =SUM(I32:I38) -> 54524240 | J39: =BS!G40-'Aging Analysis'!I39 -> 0
B41: =B4+1 -> 21 | C41: Figures for the previous year have been regrouped/ reclassified, where necessary to conform to current year’s classification.
C43: =[1]CFS!B46 -> FOR KUMAR GUPTA & ASSOCIATES
C44: =[1]CFS!B47 -> CHARTERED ACCOUNTANTS
C45: =[1]CFS!B48 -> Firm Registration No. 035355N | G45: =PL!C37 -> FOR SINGLA STEEL CORPORATION
C51: =[1]CFS!B53 -> (CA. KESHAV GUPTA) | G51: =PL!C43 -> ASHWANI KUMAR SINGLA
C52: =[1]CFS!B54 -> PROPRIETOR | G52: =PL!C44 -> PROPRIETOR
C53: =[1]CFS!B55 -> (M.NO. 553123)
C54: =[1]CFS!B56 -> UDIN : 25553123BMLDXE6873
...

Sheet Sheet4
B1: ='PL Det'!C1 -> SINGLA STEEL CORPORATION
B2: =[1]Notes!B2 -> Notes to Financial Statements for the year ended 31.03.2025
C4: ='My Contect'!E15 -> 31.03.2025 | D4: ='My Contect'!E16 -> 31.03.2024
B5: Secured Loans
B6: HDFC CC A/c | C6: =SUMIFS('Trial 2025'!H:H,'Trial 2025'!B:B,Sheet4!B6) -> 9407706 | D6: =SUMIFS('Trial 2025'!J:J,'Trial 2025'!B:B,Sheet4!B6) -> 7180440.6
C7: =SUMIFS('Trial 2025'!H:H,'Trial 2025'!B:B,Sheet4!B7) -> 0 | D7: =SUMIFS('Trial 2025'!J:J,'Trial 2025'!B:B,Sheet4!B7) -> 0
C8: =SUMIFS('Trial 2025'!H:H,'Trial 2025'!B:B,Sheet4!B8) -> 0 | D8: =SUMIFS('Trial 2025'!J:J,'Trial 2025'!B:B,Sheet4!B8) -> 0
C9: =SUMIFS('Trial 2025'!H:H,'Trial 2025'!B:B,Sheet4!B9) -> 0 | D9: =SUMIFS('Trial 2025'!J:J,'Trial 2025'!B:B,Sheet4!B9) -> 0
C11: =SUM(C6:C10) -> 9407706 | D11: =SUM(D6:D10) -> 7180440.6
E12: Opening | F12: Received | G12: Repayment | H12: Interest | I12: TDS on Interest | J12: Closing | K12: Check
B13: Loans and Advances from Related Parties
B14: Ankush Kumar Singla | C14: =SUMIFS('Trial 2025'!H:H,'Trial 2025'!B:B,Sheet4!B14) -> 0 | D14: =SUMIFS('Trial 2025'!J:J,'Trial 2025'!B:B,Sheet4!B14) -> 16473117 | E14: =D14 -> 16473117 | F14: =78545947-E14 -> 62072830 | G14: 78545947 | H14: 0 | I14: 0 | J14: =E14+F14-G14+H14-I14 -> 0 | K14: =C14-J14 -> 0
B15: Ankush Kumar Singla (HUF) | C15: =SUMIFS('Trial 2025'!H:H,'Trial 2025'!B:B,Sheet4!B15) -> 4365237 | D15: =SUMIFS('Trial 2025'!J:J,'Trial 2025'!B:B,Sheet4!B15) -> 3957616 | E15: =D15 -> 3957616 | F15: =4664537-E15 -> 706921 | G15: 299300 | H15: 0 | I15: 0 | J15: =E15+F15-G15+H15-I15 -> 4365237 | K15: =C15-J15 -> 0
B16: Ashwani Kumar HUF | C16: =SUMIFS('Trial 2025'!H:H,'Trial 2025'!B:B,Sheet4!B16) -> 4591958 | D16: =SUMIFS('Trial 2025'!J:J,'Trial 2025'!B:B,Sheet4!B16) -> 4194995 | E16: =D16 -> 4194995 | F16: =160000+748+14790+135225+186200 -> 496963 | G16: 100000 | J16: =E16+F16-G16+H16-I16 -> 4591958 | K16: =C16-J16 -> 0
B17: Manju Singla | C17: =SUMIFS('Trial 2025'!H:H,'Trial 2025'!B:B,Sheet4!B17) -> 7836374 | D17: =SUMIFS('Trial 2025'!J:J,'Trial 2025'!B:B,Sheet4!B17) -> 8765010 | E17: =D17 -> 8765010 | F17: =10436299-E17 -> 1671289 | G17: 2599925 | J17: =E17+F17-G17+H17-I17 -> 7836374 | K17: =C17-J17 -> 0
B18: Megha Singla | C18: =SUMIFS('Trial 2025'!H:H,'Trial 2025'!B:B,Sheet4!B18) -> 0 | D18: =SUMIFS('Trial 2025'!J:J,'Trial 2025'!B:B,Sheet4!B18) -> 5234036 | E18: =D18 -> 5234036 | F18: =7141080-E18 -> 1907044 | G18: 7141080 | J18: =E18+F18-G18+H18-I18 -> 0 | K18: =C18-J18 -> 0
B19: Saloni Singla | C19: =SUMIFS('Trial 2025'!H:H,'Trial 2025'!B:B,Sheet4!B19) -> 1074600 | D19: =SUMIFS('Trial 2025'!J:J,'Trial 2025'!B:B,Sheet4!B19) -> 0 | E19: =D19 -> 0 | F19: 1074600 | J19: =E19+F19-G19+H19-I19 -> 1074600 | K19: =C19-J19 -> 0
B20: Chehak Singla | C20: =SUMIFS('Trial 2025'!H:H,'Trial 2025'!B:B,Sheet4!B20) -> 1319800 | D20: =SUMIFS('Trial 2025'!J:J,'Trial 2025'!B:B,Sheet4!B20) -> 0 | E20: =D20 -> 0 | F20: 1319800 | J20: =E20+F20-G20+H20-I20 -> 1319800 | K20: =C20-J20 -> 0
C23: =SUM(C14:C21) -> 19187969 | D23: =SUM(D14:D21) -> 38624774
B25: Trade Payables | C25: =C4 -> 31.03.2025 | D25: =D4 -> 31.03.2024
A26: (i) | B26: total outstanding dues of micro enterprises and small enterprises
C28: =SUM(C27:C27) -> 0 | D28: =SUM(D27:D27) -> 0
A29: (ii) | B29: total outstanding dues of creditors other than micro enterprises and small enterprises | E29: less than 1 year | F29: 1-2 years | G29: 2-3 years | H29: More than 3 years | I29: Total
B30: Addi Alloys Pvt.Ltd | C30: =SUMIFS('Trial 2025'!H:H,'Trial 2025'!B:B,Sheet4!B30) -> 0 | D30: =SUMIFS('Trial 2025'!J:J,'Trial 2025'!B:B,Sheet4!B30) -> 55371 | H30: =C30-E30-F30-G30 -> 0 | I30: =SUM(E30:H30) -> 0 | K30: =IFERROR(VLOOKUP(B30,'Trial 2025'!B:H,9,0),) -> 0 | L30: =C30-K30 -> 0
B31: Garg Sales Corporation | C31: =SUMIFS('Trial 2025'!H:H,'Trial 2025'!B:B,Sheet4!B31) -> 14091808 | D31: =SUMIFS('Trial 2025'!J:J,'Trial 2025'!B:B,Sheet4!B31) -> 15085398 | H31: =C31-E31-F31-G31 -> 14091808 | I31: =SUM(E31:H31) -> 14091808 | K31: =IFERROR(VLOOKUP(B31,'Trial 2025'!B:H,9,0),) -> 0 | L31: =C31-K31 -> 14091808
B32: Ingottastic Llp | C32: =SUMIFS('Trial 2025'!H:H,'Trial 2025'!B:B,Sheet4!B32) -> 0 | D32: =SUMIFS('Trial 2025'!J:J,'Trial 2025'!B:B,Sheet4!B32) -> 231024 | H32: =C32-E32-F32-G32 -> 0 | I32: =SUM(E32:H32) -> 0 | K32: =IFERROR(VLOOKUP(B32,'Trial 2025'!B:H,9,0),) -> 0 | L32: =C32-K32 -> 0
B33: Monga Brothers (Unit II) | C33: =SUMIFS('Trial 2025'!H:H,'Trial 2025'!B:B,Sheet4!B33) -> 0 | D33: =SUMIFS('Trial 2025'!J:J,'Trial 2025'!B:B,Sheet4!B33) -> 100000 | H33: =C33-E33-F33-G33 -> 0 | I33: =SUM(E33:H33) -> 0 | K33: =IFERROR(VLOOKUP(B33,'Trial 2025'!B:H,9,0),) -> 0 | L33: =C33-K33 -> 0
B34: Nitin Road Carrier | C34: =SUMIFS('Trial 2025'!H:H,'Trial 2025'!B:B,Sheet4!B34) -> 149858 | D34: =SUMIFS('Trial 2025'!J:J,'Trial 2025'!B:B,Sheet4!B34) -> 28385 | E34: =C34 -> 149858 | H34: =C34-E34-F34-G34 -> 0 | I34: =SUM(E34:H34) -> 149858 | K34: =IFERROR(VLOOKUP(B34,'Trial 2025'!B:H,9,0),) -> 0 | L34: =C34-K34 -> 149858
B35: Onkar Multimetals & Alloys | C35: =SUMIFS('Trial 2025'!H:H,'Trial 2025'!B:B,Sheet4!B35) -> 0 | D35: =SUMIFS('Trial 2025'!J:J,'Trial 2025'!B:B,Sheet4!B35) -> 865 | H35: =C35-E35-F35-G35 -> 0 | I35: =SUM(E35:H35) -> 0
B36: R G D Special Ispat | C36: =SUMIFS('Trial 2025'!H:H,'Trial 2025'!B:B,Sheet4!B36) -> 105750 | D36: =SUMIFS('Trial 2025'!J:J,'Trial 2025'!B:B,Sheet4!B36) -> 122634 | E36: =C36 -> 105750 | H36: =C36-E36-F36-G36 -> 0 | I36: =SUM(E36:H36) -> 105750
B37: R.K.Steels (India) | C37: =SUMIFS('Trial 2025'!H:H,'Trial 2025'!B:B,Sheet4!B37) -> 0 | D37: =SUMIFS('Trial 2025'!J:J,'Trial 2025'!B:B,Sheet4!B37) -> 63668 | H37: =C37-E37-F37-G37 -> 0 | I37: =SUM(E37:H37) -> 0
B38: Singla Transport Service | C38: =SUMIFS('Trial 2025'!H:H,'Trial 2025'!B:B,Sheet4!B38) -> 0 | D38: =SUMIFS('Trial 2025'!J:J,'Trial 2025'!B:B,Sheet4!B38) -> 426208 | E38: =C38 -> 0 | H38: =C38-E38-F38-G38 -> 0 | I38: =SUM(E38:H38) -> 0
B39: Sonalika Agro Industries Corporation | C39: =SUMIFS('Trial 2025'!H:H,'Trial 2025'!B:B,Sheet4!B39) -> 34.64 | D39: =SUMIFS('Trial 2025'!J:J,'Trial 2025'!B:B,Sheet4!B39) -> 193.64 | H39: =C39-E39-F39-G39 -> 34.64 | I39: =SUM(E39:H39) -> 34.64
B40: Srv Steels Pvt.Ltd. Unit -2 | C40: =SUMIFS('Trial 2025'!H:H,'Trial 2025'!B:B,Sheet4!B40) -> 0 | D40: =SUMIFS('Trial 2025'!J:J,'Trial 2025'!B:B,Sheet4!B40) -> 2334684 | E40: =C40 -> 0 | H40: =C40-E40-F40-G40 -> 0 | I40: =SUM(E40:H40) -> 0
B41: Vasu Multimetals (P) Limited | C41: =SUMIFS('Trial 2025'!H:H,'Trial 2025'!B:B,Sheet4!B41) -> 0 | D41: =SUMIFS('Trial 2025'!J:J,'Trial 2025'!B:B,Sheet4!B41) -> 40139 | H41: =C41-E41-F41-G41 -> 0 | I41: =SUM(E41:H41) -> 0
B42: Ahran Multitech Private Limited | C42: =SUMIFS('Trial 2025'!H:H,'Trial 2025'!B:B,Sheet4!B42) -> 1496414 | E42: =C42 -> 1496414 | H42: =C42-E42-F42-G42 -> 0 | I42: =SUM(E42:H42) -> 1496414
B43: Sharu Industries | C43: =SUMIFS('Trial 2025'!H:H,'Trial 2025'!B:B,Sheet4!B43) -> 2351 | E43: =C43 -> 2351 | H43: =C43-E43-F43-G43 -> 0 | I43: =SUM(E43:H43) -> 2351
C45: =SUM(C30:C44) -> 15846216 | D45: =SUM(D30:D44) -> 18488570 | E45: =SUM(E30:E44) -> 1754373 | F45: =SUM(F30:F44) -> 0 | G45: =SUM(G30:G44) -> 0 | H45: =SUM(H30:H44) -> 14091843 | I45: =SUM(I30:I44) -> 15846216 | K45: =SUM(K30:K44) -> 0 | L45: 24996055 | M45: =C45-L45 -> -9149839.5
K46: 14754033
C47: =C28+C45 -> 15846216 | D47: =D28+D45 -> 18488570 | K47: =K45-K46 -> -14754033
...

Sheet Trial 2025
B1: =Sheet4!B1 -> SINGLA STEEL CORPORATION
B2: CIN: | C2: =C231 -> 4.0787445e+08 | D2: =D231 -> 4.0787445e+08
B3: Trial Balance | D3: =C2-D2 -> 0
B4: 1-Apr-2023 to 31-Mar-2024 | I4: 1-Apr-2023 to 31-Mar-2024
C5: =B1 -> SINGLA STEEL CORPORATION | E5: =C5 -> SINGLA STEEL CORPORATION | G5: =E5 -> SINGLA STEEL CORPORATION | I5: =G5 -> SINGLA STEEL CORPORATION
B6: Particulars | C6: =B4 -> 1-Apr-2023 to 31-Mar-2024 | G6: =B4 -> 1-Apr-2023 to 31-Mar-2024 | I6: =D4 -> 0
C7: P U N J A B | E7: E X P E C T E D | G7: T O T A L | I7: T O T A L
C8: Debit | D8: Credit | E8: Debit | F8: Credit | G8: Debit | H8: Credit | I8: Debit | J8: Credit
B9: Capital Account
B10: Equity Share Capital
B11: Ashwani Kumar Singla | D11: 14177491 | G11: =C11+E11 -> 0 | H11: =D11+F11 -> 14177491
B12: Reserve & Surplus | G12: =C12+E12 -> 0 | H12: =D12+F12 -> 0
B13: Loans (Liability) | G13: =C13+E13 -> 0 | H13: =D13+F13 -> 0
B14: Secured Loans | G14: =C14+E14 -> 0 | H14: =D14+F14 -> 0
B15: HDFC CC A/c | D15: 9407706 | G15: =C15+E15 -> 0 | H15: =D15+F15 -> 9407706 | J15: 7180440.6
B16: Unsecured Loans | G16: =C16+E16 -> 0 | H16: =D16+F16 -> 0
B17: Ankush Kumar Singla | G17: =C17+E17 -> 0 | H17: =D17+F17 -> 0 | J17: 16473117
B18: Ankush Kumar Singla (Huf) | D18: 4365237 | G18: =C18+E18 -> 0 | H18: =D18+F18 -> 4365237 | J18: 3957616
B19: Ashwani Kumar Huf | D19: 4591958 | G19: =C19+E19 -> 0 | H19: =D19+F19 -> 4591958 | J19: 4194995
B20: Manju Singla | D20: 7836374 | G20: =C20+E20 -> 0 | H20: =D20+F20 -> 7836374 | J20: 8765010
B21: Megha Singla | G21: =C21+E21 -> 0 | H21: =D21+F21 -> 0 | J21: 5234036
B22: Saloni Singla | D22: 1074600 | G22: =C22+E22 -> 0 | H22: =D22+F22 -> 1074600
B23: Chehak Singla | D23: 1319800 | G23: =C23+E23 -> 0 | H23: =D23+F23 -> 1319800
B24: Current Liabilities | G24: =C24+E24 -> 0 | H24: =D24+F24 -> 0
B25: Duties and Taxes | G25: =C25+E25 -> 0 | H25: =D25+F25 -> 0
B26: GST | C26: =5276.45+5276.45+96540+147010+7492.9 -> 261595.8 | D26: =19768.12+19788.12+7492+228258.4 -> 275306.64 | E26: =-C26 -> -261595.8 | F26: =E26 -> -261595.8 | G26: =C26+E26 -> 0 | H26: =D26+F26 -> 13710.84 | I26: 281077.42 | J26: 1100
B27: TDS Payable | D27: 142007 | E27: =F27 -> 0 | F27: =-C27 -> 0 | G27: =C27+E27 -> 0 | H27: =D27+F27 -> 142007 | J27: 236993
B28: TDS (under GST) Payable | D28: =20299+20299 -> 40598 | G28: =C28+E28 -> 0 | H28: =D28+F28 -> 40598
B29: TCS Payable | G29: =C29+E29 -> 0 | H29: =D29+F29 -> 0 | J29: 122981
B30: Sundry Creditors | G30: =C30+E30 -> 0 | H30: =D30+F30 -> 0
B31: Addi Alloys Pvt.Ltd | G31: =C31+E31 -> 0 | H31: =D31+F31 -> 0 | J31: 55371 | L31: =VLOOKUP(B31,Sheet4!B:C,2,0)-G31 -> 0
B32: Garg Sales Corporation | D32: 14091808 | G32: =C32+E32 -> 0 | H32: =D32+F32 -> 14091808 | J32: 15085398 | L32: =VLOOKUP(B32,Sheet4!B:C,2,0)-G32 -> 14091808
B33: Ingottastic Llp | G33: =C33+E33 -> 0 | H33: =D33+F33 -> 0 | J33: 231024 | L33: =VLOOKUP(B33,Sheet4!B:C,2,0)-G33 -> 0
B34: Monga Brothers (Unit II) | G34: =C34+E34 -> 0 | H34: =D34+F34 -> 0 | J34: 100000 | L34: =VLOOKUP(B34,Sheet4!B:C,2,0)-G34 -> 0
B35: Nitin Road Carrier | D35: 149858 | G35: =C35+E35 -> 0 | H35: =D35+F35 -> 149858 | J35: 28385 | L35: =VLOOKUP(B35,Sheet4!B:C,2,0)-G35 -> 149858
B36: Onkar Multimetals & Alloys | G36: =C36+E36 -> 0 | H36: =D36+F36 -> 0 | J36: 865 | L36: =VLOOKUP(B36,Sheet4!B:C,2,0)-G36 -> 0
B37: R G D Special Ispat | D37: 105750 | G37: =C37+E37 -> 0 | H37: =D37+F37 -> 105750 | J37: 122634 | L37: =VLOOKUP(B37,Sheet4!B:C,2,0)-G37 -> 105750
B38: R.K.Steels (India) | G38: =C38+E38 -> 0 | H38: =D38+F38 -> 0 | J38: 63668 | L38: =VLOOKUP(B38,Sheet4!B:C,2,0)-G38 -> 0
B39: Singla Transport Service | F39: =E210+E171 -> 0 | G39: =C39+E39 -> 0 | H39: =D39+F39 -> 0 | J39: 426208 | L39: =VLOOKUP(B39,Sheet4!B:C,2,0)-G39 -> 0
B40: Sonalika Agro Industries Corporation | D40: 34.64 | G40: =C40+E40 -> 0 | H40: =D40+F40 -> 34.64 | J40: 193.64 | L40: =VLOOKUP(B40,Sheet4!B:C,2,0)-G40 -> 34.64
...
